## 错误处理
* rust在大多数情况下会在编译阶段报错。
* 在rust中，将错误分为两大类： 
* 可恢复错误与不可恢复错误
* `对于可恢复错误，比如文件未找到，一般需要将报错报告为用户并再次进行操作`
* `不可以恢复错误，就是bug`


### 不可恢复错误与panic!
* `使用panic!宏执行时可以打印一段错误提示信息，会展开并清理当前的调用栈，然后退出程序`
* `调用栈展开意味着rust会沿着调用栈的反向顺序遍历所有调用函数，并依次清理这些函数中的数据`
* `除了展开，还可以选择直接终止程序，但是不会进行任何的清理工作，程序所使用的内存只能由操作系统来回收`
```rust
fn main() {
    child()
}
fn child(){
    panic!("err")
}
/*
thread 'main' panicked at 'err', src/main.rs:5:5
*
```
* `一般来说，都是在发布模式中使用终止模式，使用方法是在cargo.toml文件中添加`
```toml
[profile.release]
panic = 'abort'
```

#### panic产生的回溯信息
```rust
fn main() {
    let i = child();
    println!("i{}",i)
}
fn child()->i32{
    let v = vec![1,2,3];
    v[5]
}
```
* 可以看到提示信息
```text
    Finished dev [unoptimized + debuginfo] target(s) in 0.10s
     Running `target/debug/hello-rust`
thread 'main' panicked at 'index out of bounds: the len is 3 but the index is 5', src/main.rs:7:5
note: run with `RUST_BACKTRACE=1` environment variable to display a backtrace
```
* `通过使用 RUST_BACKTRACE=1 cargo run 可以看到回溯信息`
```text
thread 'main' panicked at 'index out of bounds: the len is 3 but the index is 5', src/main.rs:7:5
stack backtrace:
   0: rust_begin_unwind
             at /rustc/d5a82bbd26e1ad8b7401f6a718a9c57c96905483/library/std/src/panicking.rs:575:5
   1: core::panicking::panic_fmt
             at /rustc/d5a82bbd26e1ad8b7401f6a718a9c57c96905483/library/core/src/panicking.rs:64:14
   2: core::panicking::panic_bounds_check
             at /rustc/d5a82bbd26e1ad8b7401f6a718a9c57c96905483/library/core/src/panicking.rs:147:5
   3: <usize as core::slice::index::SliceIndex<[T]>>::index
             at /rustc/d5a82bbd26e1ad8b7401f6a718a9c57c96905483/library/core/src/slice/index.rs:260:10
   4: core::slice::index::<impl core::ops::index::Index<I> for [T]>::index
             at /rustc/d5a82bbd26e1ad8b7401f6a718a9c57c96905483/library/core/src/slice/index.rs:18:9
   5: <alloc::vec::Vec<T,A> as core::ops::index::Index<I>>::index
             at /rustc/d5a82bbd26e1ad8b7401f6a718a9c57c96905483/library/alloc/src/vec/mod.rs:2727:9
   6: hello_rust::child
             at ./src/main.rs:7:5
   7: hello_rust::main
             at ./src/main.rs:2:13
   8: core::ops::function::FnOnce::call_once
             at /rustc/d5a82bbd26e1ad8b7401f6a718a9c57c96905483/library/core/src/ops/function.rs:507:5
note: Some details are omitted, run with `RUST_BACKTRACE=full` for a verbose backtrace.
```
* 如果想要更多回溯信息，那么使用RUST_BACKTRACE=full

### 可恢复错误与Result
* 大部分的错误都没有很严重，需要程序停止。所以这个使用可以使用可恢复错误
* 一般使用Result类型处理可能失败的情况
```rust
enum Result<T, E> {
    Ok(T),
    Err(E),
}
```
* 看个例子
```rust
use std::fs::File;

fn main() {
    let f = File::open("a.txt");
    println!("f{:?}",f);
    // fErr(Os { code: 2, kind: NotFound, message: "No such file or directory" })
}
```
* `文件没有找到，但是并没有终止程序，而是响应了一个fErr错误`
* 进行match
```rust
use std::fs::File;

fn main() {
    let f = File::open("a.txt");

    let a  = match f {
        Ok(file) => file,
        Err(err) =>{
            panic!("err:{:?}",err);
        }
    };
    // 没有文件
    // thread 'main' panicked at 'err:Os { code: 2, kind: NotFound, message: "No such file or directory" }', src/main.rs:9:13
    // println!("a{:?}",a);


    // 在根目录下创建a.txt文件
    // aFile { fd: 3, path: "/Users/xielipei/Documents/rustProject/hello-rust/a.txt", read: true, write: false }
    println!("a{:?}",a);
}
```
* `match嵌套match`
```rust
use std::fs::File;
use std::io::ErrorKind;

fn main() {
    let f = File::open("a.txt");

    let a  = match f {
        Ok(file) => {
            println!("已存在");
            file
        },
        Err(err) =>{
            match err.kind() {
                ErrorKind::NotFound => {
                    match File::create("a.txt") {
                        Ok(file) => file,
                        Err(err) =>{
                            panic!("create err:{:?}",err);
                        }
                    }
                },
                other_err => panic!("other err:{:?}",other_err)
            }
        }
    };
    println!("a:{:?}",a);
    // 第一次运行没有a.txt,会自动创建
    // a:File { fd: 3, path: "/Users/xielipei/Documents/rustProject/hello-rust/a.txt", read: false, write: true }
    // 生成空文件

    // 第二次运行，已存在文件
    /*
    已存在
    a:File { fd: 3, path: "/Users/xielipei/Documents/rustProject/hello-rust/a.txt", read: true, write: false }
    */
}
```

#### unwrap处理panic!
```rust
use std::fs::File;

fn main() {
    // unwrap: 返回包含的 Ok 值，消耗 self 值。因为这个函数可能会出现 panic，所以通常不鼓励使用它。
    // 相反，更喜欢使用模式匹配并显式处理 Err 情况，或者调用 unwrap_or、unwrap_or_else 或 unwrap_or_default。
    // Panics 如果值为 Err 则出现 Panics，并由 Err 的值提供 panic 消息。
    let f = File::open("a.txt").unwrap();
    println!("f:{:?}",f);
    // 存在对应文件
    // f:File { fd: 3, path: "/Users/xielipei/Documents/rustProject/hello-rust/a.txt", read: true, write: false }

    // 不存在
    // thread 'main' panicked at 'called `Result::unwrap()` on an `Err` value: Os { code: 2, kind: NotFound, message: "No such file or directory" }', src/main.rs:7:33
}
```

#### expect也可以处理panic且添加附加错误消息
```rust
use std::fs::File;

fn main() {
    // expect会在unwrap的基础上，在错误消息上添加上我们的msg 附加错误消息
    let f = File::open("a.txt").expect("附加错误消息");
    println!("f:{:?}",f);
    // 存在对应文件
    // f:File { fd: 3, path: "/Users/xielipei/Documents/rustProject/hello-rust/a.txt", read: true, write: false }

    // 不存在
    // thread 'main' panicked at '附加错误消息: Os { code: 2, kind: NotFound, message: "No such file or directory" }', src/main.rs:5:33
}
```

#### 函数响应错误
* `看个例子，读取文件内容，写入字符串String`
```rust
use std::io;
use std::io::Read;
use std::fs::File;

fn main() {
    let res = read_username_from_file();
    println!("res:{:?}",res);
    // 不存在
    // res:Err(Os { code: 2, kind: NotFound, message: "No such file or directory" })

    // 存在，空文件
    // res:Ok("")

    // 存在，内容为haha
    // res:Ok("haha\n")
    // 就是把内容读取出来了！
}

fn read_username_from_file() -> Result<String, io::Error> {
    let f = File::open("hello.txt");

    let mut f = match f {
        Ok(file) => file,
        Err(e) => return Err(e),
    };

    // 创建一个可变的String
    let mut s = String::new();

    // read_to_string 任意实现可能会覆盖向量的全部内容
    match f.read_to_string(&mut s) {
        Ok(_) => Ok(s), // 写入s
        Err(e) => Err(e),
    }
}
```

#### 传播错误的快捷方式?运算符
* `将?运算符放在Result值之后，如果Result返回的值是Ok,那么包含在Ok里面的值就会作为表达式的结果返回并继续执行程序`
* `如果值是Err，那么这个值就会相当于被return了，响应给调用者`
```rust
use std::io;
use std::io::Read;
use std::fs::File;

fn main() {
    let res = read_username_from_file();
    println!("res:{:?}",res);
    // 不存在
    // res:Err(Os { code: 2, kind: NotFound, message: "No such file or directory" })

    // 存在，空文件
    // res:Ok("")

    // 存在，内容为haha
    // res:Ok("haha\n")
    // 就是把内容读取出来了！
}

fn read_username_from_file() -> Result<String, io::Error> {
    let mut f = File::open("hello.txt")?;
    // 创建一个可变的String
    let mut s = String::new();
    // read_to_string 任意实现可能会覆盖向量的全部内容
    // 写入字符串s
    f.read_to_string(&mut s)?;
    Ok(s)
}
```

#### rust还有链式调用
* 把上面的代码再简化一下
```rust
use std::io;
use std::io::Read;
use std::fs::File;

fn main() {
    let res = read_username_from_file();
    println!("res:{:?}",res);
    // 不存在
    // res:Err(Os { code: 2, kind: NotFound, message: "No such file or directory" })

    // 存在，空文件
    // res:Ok("")

    // 存在，内容为haha
    // res:Ok("haha\n")
    // 就是把内容读取出来了！
}

fn read_username_from_file() -> Result<String, io::Error> {
    // 创建一个可变的String
    let mut s = String::new();
    File::open("hello.txt")?.read_to_string(&mut s)?;
    Ok(s)
}
```

#### 使用fs可以直接读取文件内容
```rust
use std::{fs, io};

fn main() {
    let res = read_username_from_file();
    println!("res:{:?}",res);
    // 不存在
    // res:Err(Os { code: 2, kind: NotFound, message: "No such file or directory" })

    // 存在，空文件
    // res:Ok("")

    // 存在，内容为haha
    // res:Ok("haha\n")
    // 就是把内容读取出来了！
}

fn read_username_from_file() ->  io::Result<String> {
    fs::read_to_string("hello.txt")
}
```



