## 异常
* 以Throwable为根，Java定义了非常多的异常类，表示各种类型的异常

* `Throwable是所有异常的基类，它有两个子类：Error和Exception`

1. `Error表示系统错误或资源耗尽，由Java系统自己使用，应用程序不应抛出和处理`，比如
* 图中列出的虚拟机错误（VirtualMacheError）及其子类内存溢出错误（OutOfMemory-Error）和栈溢出错误（StackOverflowError）

2. `Exception表示应用程序错误`，它有很多子类，应用程序也可以通过继承Exception或其子类创建自定义异常，
* 图中列出了三个直接子类：IOException（输入输出I/O异常）、RuntimeException（运行时异常）、SQLException（数据库SQL异常）

#### runtimeException
* RuntimeException比较特殊，它的名字有点误导，因为其他异常也是运行时产生的，它表示的`实际含义是未受检异常（unchecked exception）`，
* 相对而言，Exception的其他子类和Exception自身则是受检异常（checked exception）,Error及其子类也是未受检异常。


#### 未受检异常和受检异常
* 受检（checked）和未受检（unchecked）的区别在于Java如何处理这两种异常。
* `对于受检异常，Java会强制要求程序员进行处理，否则会有编译错误`，
* 而对于未受检异常则没有这个要求。

#### 多个异常
```text
        try {
              //可能抛出 ExceptionA和ExceptionB
        } catch (ExceptionA | ExceptionB e) {
              e.printStackTrace();
        }
```

#### finally
* finally语句有一个执行细节，如果在try或者catch语句内有return语句，
* `则return语句在finally语句执行结束后才执行，但finally并不能改变返回值`
```text
        public static int test(){
            int ret = 0;
            try{
                  return ret;
              }finally{
                  ret = 2;
              }
          }
```
* 这个函数的返回值是0，而不是2。实际执行过程是：
* `在执行到try内的return ret；语句前，会先将返回值ret保存在一个临时变量中，`
* 然后才执行finally语句，最后try再返回那个临时变量，finally中对ret的修改不会被返回。

* `如果在finally中也有return语句呢？try和catch内的return会丢失，实际会返回finally中的返回值。`
* `finally中有return不仅会覆盖try和catch内的返回值，还会掩盖try和catch内的异常，就像异常没有发生一样`
```text
        public static int test(){
            int ret = 0;
            try{
                int a = 5/0;
                return ret;
            }finally{
                return 2;
            }
        }
```



